<?xml version="1.0" ?>
<robot name="v4_6DoF">

<!-- ********** KINEMATIC PROPERTIES (JOINTS) ********** -->
<!-- I guess goal is all origin orientations all lined up when fully extended up -->
<joint name="world_joint" type="fixed">
    <parent link="world"/>
    <child link="base_link"/>
    <origin rpy="0.0 0.0 0.0" xyz="0.0 0.0 0.0"/>
</joint>

<!-- R1 -->
<joint name="joint1" type="continuous">
    <parent link="base_link"/>
    <child link="link1"/>
    <origin rpy="0.0 0.0 0.0" xyz="0.0 0.02545 0.0"/>
    <axis xyz="0 1 0"/>
</joint>

<!-- T1  rotated 90 degrees from R1-->
<joint name="joint2" type="continuous">
    <parent link="link1"/>
    <child link="link2"/>
    <origin rpy="1.570796325 0.0 0.0" xyz="0.0 0.145925 0.0"/>
    <axis xyz="0 0 1"/>
</joint>

<!-- T2 -->
<joint name="joint3" type="continuous">
    <parent link="link2"/>
    <child link="link3"/>
    <origin rpy="-1.570796325 0.0 0.0" xyz="0.0 0.25 0"/>
    <axis xyz="0 0 1"/>
</joint>

<!-- R2 -->
<joint name="joint4" type="continuous">
    <parent link="link3"/>
    <child link="link4"/>
    <origin rpy="-1.570796325 0.0 0.0" xyz="0.0 0.06825 0.0"/>
    <axis xyz="0 1 0"/>
</joint>

<!-- T3 -->
<joint name="joint5" type="continuous">
    <parent link="link4"/>
    <child link="link5"/>
    <origin rpy="0.0 0.0 0.0" xyz="0.0 0.1783 0.0"/>
    <axis xyz="0 0 1"/>
</joint>

<!-- R3 -->
<joint name="joint6" type="continuous">
    <parent link="link5"/>
    <child link="link6"/>
    <origin rpy="0.0 0.0 0.0" xyz="0.0 0.023282 0.0"/>
    <axis xyz="0 1 0"/>
</joint>

<joint name="ee_joint" type="fixed">
    <origin rpy="0 0 0" xyz="0.0 0.0 0.0"/>
    <parent link="link6"/>
    <child link="ee_link"/>
</joint>

<!-- ********** INERTIAL PROPERTIES (LINKS) ********** -->
<link name="world"/>
<link name="base_link">
    <inertial>
        <mass value="1.647"/>
        <origin ix="0.963 -0.270 0.0" iy="-0.001 -0.004 -1.000" iz="0.27 0.963 -0.004" xyz="-0.201605 0.052782 0.0"/>
        <inertia_CoM ixx="0.003431311444" ixy="-0.001737273424" ixz="0.000002098979"
                 iyy="0.009133847653" iyz="0.000004170499" izz="0.008439899356"/>
        <!-- <inertia_joint ixx="0.008020766055" ixy="-0.019266949518" ixz="0.000021243953"
                 iyy="0.076089501798" iyz="0.000000841852" izz="0.079984997164"/> -->
    </inertial>
</link>

<link name="link1">
    <inertial>
        <mass value="3.631"/>
        <origin ix="0.992 0.124 -0.019" iy="-0.011 -0.063 -0.998" iz="-0.125 0.990 -0.061" xyz="-0.128066 0.053053 0.00198"/>
        <inertia_CoM ixx="0.006116309" ixy="0.000646755" ixz="-0.000096444"
                 iyy="0.011214891" iyz="0.000004513" izz="0.011027782"/>
        <!-- <inertia_joint ixx="0.015968504641" ixy="-0.023557660073" ixz="-0.001017143456"
                 iyy="0.070779444991" iyz="0.000378734993" izz="0.080416061689"/> -->
    </inertial>
</link>

<link name="link2">
    <inertial>
        <mass value="2.071"/>
        <origin ix="0.001 1.0 0.002" iy="0.0 -0.002 1.0" iz="1.0 -0.001 0.0" xyz="0.00012 0.113575 0.000297"/>
        <inertia_CoM ixx="0.015468420" ixy="0.000009620" ixz="-0.000000073"
                 iyy="0.003255711" iyz="0.000024530" izz="0.014217237"/>
        <inertia_joint ixx="0.042186793163" ixy="0.000037781375" ixz="-0.000000000066"
                 iyy="0.003255923507" iyz="0.000094423532" izz="0.040935457134"/>
    </inertial>
</link>

<link name="link3">
    <inertial>
        <mass value="0.657"/>
        <origin ix="0.012 1.0 0.0" iy="0.0 0.0 1.0" iz="1.0 -0.012 0.0" xyz="0.001781 0.009667 0.0"/>
        <inertia_CoM ixx="0.000783468" ixy="0.000003308" ixz="-0.000000001"
                 iyy="0.000509087" iyz="-0.000000003" izz="0.000751864"/>
        <inertia_joint ixx="0.000844922018" ixy="0.000014631065" ixz="-0.000000001732"
                 iyy="0.000511172759" iyz="-0.000000006794" izz="0.000751864069"/>
    </inertial>
</link>

<link name="link4">
    <inertial>
        <mass value="0.448"/>
        <origin ix="0.0 1.0 0.0" iy="0.0 0.0 1.0" iz="1.0 0.0 0.0" xyz="0.0 0.089414 0.0"/>
        <inertia_CoM ixx="0.001043105" ixy="0.0" ixz="0.0"
                 iyy="0.000402733" iyz="0.000000003" izz="0.004334995"/>
        <inertia_joint ixx="0.004622908539" ixy="0.000000000014" ixz="-0.000000000035"
                 iyy="0.000402732662" iyz="-0.000000003387" izz="0.004334994790"/>
        
    </inertial>
</link>

<link name="link5">
    <inertial>
        <mass value="0.095"/>
        <origin ix="0.0 0.0 1.0" iy="0.0 -1.0 0.0" iz="1.0 0.0 0.0" xyz="0.0 0.004205 0.0"/>
        <inertia_CoM ixx="0.000135895367" ixy="0.000000006402" ixz="0.0"
                 iyy="0.000131515393" iyz="0.000000065773" izz="0.000024502299"/>
        <inertia_joint ixx="0.000137571766" ixy="0.0" ixz="0.0"
                 iyy="0.000131515419" iyz="-0.000000064336" izz="0.000026178721"/>
    </inertial>
</link>

<link name="link6">
    <inertial>
        <mass value="0.008"/>
        <origin ix="1.0 1.0 0.0" iy="0.0 0.0 -1.0" iz="0.0 1.0 0.0" xyz="0.0 -0.05294 0.0"/>
        <inertia_CoM ixx="0.000000380346" ixy="0.0" ixz="0.0"
                 iyy="0.000000524384" iyz="0.0" izz="0.000000604225"/>
    </inertial>
</link>

<link name="ee_link"/>

</robot>